Workbook

Sheet 0_README
B2: Charcoal Cost Build-Up & Tiered Supply Curve — v6
B3: Bottom-up charcoal cost (Emilio's chain) + tiered supply curve (Emilio's quantity axis).
B5: What is in this workbook
B6: 1_Wood — wood cost (R$/t wood) from land cost, productivity, density.
B7: 2_Charcoaling — charcoal cost (R$/t charcoal): wood + carbonisation (CGEE 2015).
B8: 3_BuildUp — Low / High R$/GJ with financial discounting (Emilio Step 3).
B9: 4_FX_to_USD — currency conversion R$/GJ -> USD/GJ for the model.
B10: 5_Tiers — EIGHT-TIER supply curve (USD/GJ vs PJ/year), to feed the Python script.
B13: Colour code
B14: BLUE = editable input
B15: BLACK = formula / calculated
B16: GREEN = pulled from another sheet
... B23: (c) pulp project, not charcoal (planting cost similar; downstream differs).

Sheet 1_Wood
B2: Step 1 — Cost of Wood (Eucalyptus)
B3: Goal: convert land cost (R$/ha) into wood cost (R$/t wood).
A5: INPUTS
B6: Parameter | C6: Value | D6: Unit | F6: Source / note
B7: Land / establishment cost | C7: 27778 | D7: R$/ha | F7: Bracell-BTG (R$1.5bn / 54k ha). See 0_README caveats.
B8: Forestry productivity (MAI) | C8: 40 | D8: m3/ha/yr | F8: Piketty et al. (2009): mean commercial Eucalyptus ~40 m3/ha/yr.
B9: Rotation length | C9: 7 | D9: years | F9: BTG/Eco Invest term matched to 7-yr Eucalyptus cycle.
B10: Wood basic density (dry) | C10: 0.5 | D10: t/m3 | F10: Souza & Pacca (2021), Tab 1. Replaces 0.25 from Otto thesis (suspected typo).
A12: CALCULATED
B13: Result | C13: Value | D13: Unit | F13: Logic
B14: Wood volume per ha (1 rotation) | C14: =C8*C9 -> 280 | D14: m3/ha | F14: MAI x rotation
B15: Wood mass per ha (1 rotation) | C15: =C14*C10 -> 140 | D15: t wood/ha | F15: volume x basic density
B16: Wood cost (undiscounted) | C16: =C7/C15 -> 198.41429 | D16: R$/t wood | F16: land cost / wood mass per ha
B18: Discounting (Emilio Step 3) is applied in 3_BuildUp.

Sheet 2_Charcoaling
B2: Step 2 — Charcoaling (wood -> charcoal)
B3: Mass loss in carbonisation + process cost + environmental control.
A5: INPUTS
B6: Parameter | C6: Low | D6: High | E6: Unit | G6: Source / note
B7: Gravimetric yield | C7: 0.26 | D7: same | E7: t charcoal/t wood | G7: Souza & Pacca (2021) / CGEE (2015). Range 0.26-0.30; 0.26 is the traditional-kiln baseline.
B8: Carbonisation process cost | C8: 115 | D8: 138 | E8: R$/t charcoal | G8: CGEE (2015) Tab.33: Low = trad. kiln (R$30k/260 t.cv); High = improved (R$36k/260 t.cv).
B9: Environmental control / tar recovery | C9: 0 | D9: 0 | E9: R$/t charcoal
B10: Charcoal LHV | C10: 6460 | D10: same | E10: kcal/kg | G10: Souza & Pacca (2021) / Brazilian Energy Balance.
A12: CALCULATED
B13: Result | C13: Low | D13: High | E13: Unit | G13: Logic
B14: Wood needed per t charcoal | C14: =1/C7 -> 3.8461538 | D14: =C14 -> 3.8461538 | E14: t wood / t charcoal | G14: 1 / gravimetric yield
B15: Wood cost passed into charcoal | C15: ='1_Wood'!C16*C14 -> 763.13187 | D15: ='1_Wood'!C16*D14 -> 763.13187 | E15: R$/t charcoal | G15: wood cost x wood-per-charcoal (undiscounted)
B16: Charcoaling cost (process) | C16: =C8+C9 -> 115 | D16: =D8+D9 -> 138 | E16: R$/t charcoal | G16: process; environmental embedded in modern-kiln Opex (CGEE)
B17: Charcoal LHV in GJ/t | C17: =C10*4.1868/1000 -> 27.046728 | D17: =C17 -> 27.046728 | E17: GJ/t charcoal | G17: kcal/kg -> GJ/t : x4.1868/1000

Sheet 3_BuildUp
B2: Step 3 — Cost Build-Up: Low vs High charcoal price (R$)
B3: Combines wood + charcoaling + financial discounting (Emilio Step 3).
A5: FINANCIAL ASSUMPTIONS
B6: Parameter | C6: Value | D6: Unit | G6: Source / note
B7: Academic discount rate (Low case) | C7: 0.08 | D7: real/yr | G7: Typical academic WACC.
B8: Market discount rate (High case) | C8: 0.15 | D8: real/yr | G8: real market rates exceed academic ones.
B9: Capital immobilisation time | C9: 7 | D9: years | G9: Eucalyptus cycle (~7 yrs to first harvest).
A11: CHARCOAL PRICE BUILD-UP (R$)
B12: Component | C12: Low (academic) | D12: High (market) | E12: Unit | G12: Logic
B13: Wood cost component (undiscounted) | C13: ='2_Charcoaling'!C15 -> 763.13187 | D13: ='2_Charcoaling'!C15 -> 763.13187 | E13: R$/t charcoal | G13: same wood cost before discounting
B14: Discount multiplier on wood capital | C14: =(1+C7)^C9 -> 1.7138243 | D14: =(1+C8)^C9 -> 2.6600199 | E14: factor | G14: (1+rate)^years
B15: Wood cost after discounting | C15: =C13*C14 -> 1307.8739 | D15: =D13*D14 -> 2029.9459 | E15: R$/t charcoal | G15: wood x discount
B16: Charcoaling cost (process + env.) | C16: ='2_Charcoaling'!C16 -> 115 | D16: ='2_Charcoaling'!D16 -> 138 | E16: R$/t charcoal | G16: not discounted
B17: TOTAL charcoal cost | C17: =C15+C16 -> 1422.8739 | D17: =D15+D16 -> 2167.9459 | E17: R$/t charcoal | G17: discounted wood + charcoaling
B18: TOTAL charcoal cost per GJ | C18: =C17/'2_Charcoaling'!C17 -> 52.607987 | D18: =D17/'2_Charcoaling'!C17 -> 80.155572 | E18: R$/GJ | G18: total / LHV(GJ/t)
B19: Note: charcoaling cost now Low/High differentiated (CGEE 2015 / Brito 2014).
B20: Note: environmental control removed - embedded in Opex of modern kilns per CGEE.

Sheet 4_FX_to_USD
B2: Step 4 — Currency conversion R$/GJ -> USD/GJ
B3: The optimisation model runs in USD. Convert here, with explicit FX rate.
A5: EXCHANGE RATE
B6: Parameter | C6: Value | D6: Unit | G6: Source / note
B7: BRL / USD exchange rate | C7: 5 | D7: R$ per USD | G7: Approximate average rate; declare in methodology. Update if needed.
A9: CONVERTED PRICES (USD/GJ)
B10: Item | C10: Low (academic) | D10: High (market) | E10: Unit | G10: Logic
B11: Charcoal price (USD/GJ) | C11: ='3_BuildUp'!C18/$C$7 -> 10.521597 | D11: ='3_BuildUp'!D18/$C$7 -> 16.031114 | E11: USD/GJ | G11: price R$/GJ divided by FX
A13: CROSS-CHECK with current model value
B14: Item | C14: Value | D14: Unit | G14: Source / note
B15: Charcoal price in model today (USD/GJ) | C15: 9.8 | D15: USD/GJ | G15: From Model_Config Fuel_Prices, 2023 onwards.
B16: Low / Model ratio | C16: =C11/C15 -> 1.0736324 | D16: ratio | G16: How much higher Low (bottom-up academic) is vs current model
B17: High / Model ratio | C17: =D11/C15 -> 1.635828 | D17: ratio | G17: How much higher High (bottom-up market) is vs current model

Sheet 5_Tiers
B2: Step 5 — Tiered Charcoal Supply Curve (8 tiers, USD/GJ vs PJ/year)
B3: Marginal-cost stepwise supply curve. Replaces the endogenous/combined price scheme.
B4: Implemented in the optimisation script via CHARCOAL_TIER_WIDTH_PJ and CHARCOAL_TIER_PRICE.
A6: CALIBRATION ANCHORS
B7: Anchor | C7: Value | D7: Unit | H7: Source
B8: Current consumption (D_ref from V20_10) | C8: 36 | D8: PJ/year | H8: resolve_charcoal_dref() output: 36,308,562 GJ ~= 36 PJ. Rounded.
B9: Physical cap (aditional information) | C9: 461 | D9: PJ/year | H9: Hebeda (2024); Pinto et al. (2018): 461,450 TJ = 461 PJ. Hard upper bound.
B10: Tier 1 low price (current model) | C10: 9.8 | D10: USD/GJ | H10: Current Fuel_Prices value. Anchors the cheap, consolidated supply.
B11: Bottom-up High (from 4_FX_to_USD) | C11: 16.03 | D11: USD/GJ | H11: High case from this workbook = 4_FX_to_USD!D11. Used to anchor the upper part of the curve.
B12: Highest tier price (scenario) | C12: 32 | D12: USD/GJ | H12: Top tier above bottom-up High - represents "pessimistic frontier" beyond what bottom-up captures.
A14: EIGHT-TIER SUPPLY CURVE (edit BLUE cells to recalibrate)
B15: Tier | C15: Width (PJ/yr) | D15: Price (USD/GJ) | E15: Cum. ceiling (PJ) | F15: Cum. cost at ceiling (M USD) | G15: Implied elasticity (Soares et al. (2004), 2SLS: 1.25)
B16: Tier 1 - consolidated supply | C16: 25 | D16: 9.8 | E16: =C16 -> 25 | F16: =C16*D16 -> 245
B17: Tier 2 - early expansion | C17: 10 | D17: 13 | E17: =E16+C17 -> 35 | F17: =F16+C17*D17 -> 375 | G17: =LN(E17/E16)/LN(D17/D16) -> 1.1907699
B18: Tier 3 - mid expansion | C18: 10 | D18: 16 | E18: =E17+C18 -> 45 | F18: =F17+C18*D18 -> 535 | G18: =LN(E18/E17)/LN(D18/D17) -> 1.210341
B19: Tier 4 - late expansion | C19: 10 | D19: 19 | E19: =E18+C19 -> 55 | F19: =F18+C19*D19 -> 725 | G19: =LN(E19/E18)/LN(D19/D18) -> 1.1677067
B20: Tier 5 - frontier supply | C20: 10 | D20: 22 | E20: =E19+C20 -> 65 | F20: =F19+C20*D20 -> 945 | G20: =LN(E20/E19)/LN(D20/D19) -> 1.1394961
B21: Tier 6 - exhaustion premium | C21: 10 | D21: 25 | E21: =E20+C21 -> 75 | F21: =F20+C21*D21 -> 1195 | G21: =LN(E21/E20)/LN(D21/D20) -> 1.1194326
B22: Tier 7 - extension | C22: 25 | D22: 28 | E22: =E21+C22 -> 100 | F22: =F21+C22*D22 -> 1895 | G22: =LN(E22/E21)/LN(D22/D21) -> 2.5384753
B23: Tier 8 - extension (top of curve) | C23: 50 | D23: 32 | E23: =E22+C23 -> 150 | F23: =F22+C23*D23 -> 3495 | G23: =LN(E23/E22)/LN(D23/D22) -> 3.0364778
B25: TOTAL | C25: =SUM(C16:C23) -> 150 | E25: =E23 -> 150 | F25: =F23 -> 3495 | G25: =LN(E23/E16)/LN(D23/D16) -> 1.5141371
A27: CONSISTENCY CHECKS
B28: Sum of tiers vs physical cap (461 PJ) | C28: =IF(C25<=C9,"OK - within Constraint E","EXCEEDS PHYSICAL CAP") -> OK - within Constraint E
B29: Tier 1 covers current consumption (36 PJ)? | C29: =IF(C16>=C8,"OK - T1 covers current","T1 BELOW CURRENT - bad calibration") -> T1 BELOW CURRENT - bad calibration
B30: Prices monotonically increasing? | C30: =IF(AND(D17>=D16,D18>=D17,D19>=D18,D20>=D19,D21>=D20),"OK - convex curve","NON-MONOTONIC - solver may not converge") -> OK - convex curve
A32: PROBE: marginal & average price at sample demand levels
B33: Demand level | C33: GJ/year | D33: PJ/year | E33: Marginal price (USD/GJ) | F33: Avg blended (USD/GJ)
B34: Current consumption (D_ref) | C34: 36000000 | D34: 36 | E34: =IF(D34<=$E$16,$D$16,IF(D34<=$E$17,$D$17,IF(D34<=$E$18,$D$18,IF(D34<=$E$19,$D$19,IF(D34<=$E$20,$D$20,$D$21))))) -> 16 | F34: =IF(D34<=$E$16, $D$16,IF(D34<=$E$17, ($F$16 + (D34-$E$16)*$D$17)/D34,IF(D34<=$E$18, ($F$17 + (D34-$E$17)*$D$18)/D34,IF(D34<=$E$19, ($F$18 + (D34-$E$18)*$D$19)/D34,IF(D34<=$E$20, ($F$19 + (D34-$E$19)*$D$20)/D34,($F$20 + (D34-$E$20)*$D$21)/D34))))) -> 10.861111
B35: Tier 1 ceiling | C35: 25000000 | D35: 25 | E35: 9.8 | F35: =IF(D35<=$E$16, $D$16,IF(D35<=$E$17, ($F$16 + (D35-$E$16)*$D$17)/D35,IF(D35<=$E$18, ($F$17 + (D35-$E$17)*$D$18)/D35,IF(D35<=$E$19, ($F$18 + (D35-$E$18)*$D$19)/D35,IF(D35<=$E$20, ($F$19 + (D35-$E$19)*$D$20)/D35,($F$20 + (D35-$E$20)*$D$21)/D35))))) -> 9.8
B36: Tier 2 ceiling | C36: 35000000 | D36: 35 | E36: 13 | F36: =IF(D36<=$E$16, $D$16,IF(D36<=$E$17, ($F$16 + (D36-$E$16)*$D$17)/D36,IF(D36<=$E$18, ($F$17 + (D36-$E$17)*$D$18)/D36,IF(D36<=$E$19, ($F$18 + (D36-$E$18)*$D$19)/D36,IF(D36<=$E$20, ($F$19 + (D36-$E$19)*$D$20)/D36,($F$20 + (D36-$E$20)*$D$21)/D36))))) -> 10.714286
B37: Tier 3 ceiling | C37: 45000000 | D37: 45 | E37: 16 | F37: =IF(D37<=$E$16, $D$16,IF(D37<=$E$17, ($F$16 + (D37-$E$16)*$D$17)/D37,IF(D37<=$E$18, ($F$17 + (D37-$E$17)*$D$18)/D37,IF(D37<=$E$19, ($F$18 + (D37-$E$18)*$D$19)/D37,IF(D37<=$E$20, ($F$19 + (D37-$E$19)*$D$20)/D37,($F$20 + (D37-$E$20)*$D$21)/D37))))) -> 11.888889
B38: Tier 4 ceiling | C38: 55000000 | D38: 55 | E38: 19 | F38: =IF(D38<=$E$16, $D$16,IF(D38<=$E$17, ($F$16 + (D38-$E$16)*$D$17)/D38,IF(D38<=$E$18, ($F$17 + (D38-$E$17)*$D$18)/D38,IF(D38<=$E$19, ($F$18 + (D38-$E$18)*$D$19)/D38,IF(D38<=$E$20, ($F$19 + (D38-$E$19)*$D$20)/D38,($F$20 + (D38-$E$20)*$D$21)/D38))))) -> 13.181818
B39: Tier 5 ceiling | C39: 65000000 | D39: 65 | E39: 22 | F39: =IF(D39<=$E$16, $D$16,IF(D39<=$E$17, ($F$16 + (D39-$E$16)*$D$17)/D39,IF(D39<=$E$18, ($F$17 + (D39-$E$17)*$D$18)/D39,IF(D39<=$E$19, ($F$18 + (D39-$E$18)*$D$19)/D39,IF(D39<=$E$20, ($F$19 + (D39-$E$19)*$D$20)/D39,($F$20 + (D39-$E$20)*$D$21)/D39))))) -> 14.538462
B40: Tier 6 ceiling | C40: 75000000 | D40: 75 | E40: 25 | F40: =IF(D40<=$E$16, $D$16,IF(D40<=$E$17, ($F$16 + (D40-$E$16)*$D$17)/D40,IF(D40<=$E$18, ($F$17 + (D40-$E$17)*$D$18)/D40,IF(D40<=$E$19, ($F$18 + (D40-$E$18)*$D$19)/D40,IF(D40<=$E$20, ($F$19 + (D40-$E$19)*$D$20)/D40,($F$20 + (D40-$E$20)*$D$21)/D40))))) -> 15.933333
B41: Tier 7 ceiling | C41: 100000000 | D41: 100 | E41: 28 | F41: =IF(D41<=$E$16, $D$16,IF(D41<=$E$17, ($F$16 + (D41-$E$16)*$D$17)/D41,IF(D41<=$E$18, ($F$17 + (D41-$E$17)*$D$18)/D41,IF(D41<=$E$19, ($F$18 + (D41-$E$18)*$D$19)/D41,IF(D41<=$E$20, ($F$19 + (D41-$E$19)*$D$20)/D41,($F$20 + (D41-$E$20)*$D$21)/D41))))) -> 18.2
B42: Tier 8 ceiling | C42: 150000000 | D42: 150 | E42: 32 | F42: =IF(D42<=$E$16, $D$16,IF(D42<=$E$17, ($F$16 + (D42-$E$16)*$D$17)/D42,IF(D42<=$E$18, ($F$17 + (D42-$E$17)*$D$18)/D42,IF(D42<=$E$19, ($F$18 + (D42-$E$18)*$D$19)/D42,IF(D42<=$E$20, ($F$19 + (D42-$E$19)*$D$20)/D42,($F$20 + (D42-$E$20)*$D$21)/D42))))) -> 20.466667
A44: IMPLEMENTATION IN THE PYTHON MODEL
B45: Copy these lines into the Python script:
B46: CHARCOAL_TIER_WIDTH_PJ | C46: [25.0, 10.0, 10.0, 10.0, 10.0, 10.0, 25.0, 50.0]
B47: CHARCOAL_TIER_PRICE | C47: [9.8, 13.0, 16.0, 19.0, 22.0, 25.0, 28.0, 32.0]
...
